<?xml version="1.0" encoding="utf-8"?>
<robot name="jetauto_arm" xmlns:xacro="http://ros.org/wiki/xacro">
  <xacro:property name="M_PI"   value="3.1415926535897931"/>

  <link
    name="link1">
    <inertial>
      <origin xyz="-0.000559793370378037 1.72705471198076E-05 0.0134151597525313" />
       <mass
        value="0.018996290781889" />
      <inertia
        ixx="3.52401713486466E-06"
        ixy="-9.57766622211234E-11"
        ixz="1.77834467690429E-11"
        iyy="2.92480468671507E-06"
        iyz="2.27263787135776E-08"
        izz="2.43231516201483E-06" />
    </inertial>
    <visual>
      <origin
        xyz="0 0 0"
        rpy="0 0 0" />
      <geometry>
        <mesh
          filename="package://jetauto_description/meshes/arm/link1.stl" />
      </geometry>
      <material name="green"/>
    </visual>
    <collision>
      <origin
        xyz="0 0 0"
        rpy="0 0 0" />
      <geometry>
        <mesh
          filename="package://jetauto_description/meshes/arm/link1.stl" />
      </geometry>
    </collision>
  </link>
  <joint
    name="joint1"
    type="revolute">
    <origin
      xyz="0.0230930273357735 0 0.156176218742268"
      rpy="0 0 -${M_PI/2}" />
    <parent
      link="base_link" />
    <child
      link="link1" />
    <axis
      xyz="0 0 -1" />
    <limit
      lower="-2.09"
      upper="2.09"
      effort="1000"
      velocity="10" />
  </joint>
  <link
    name="servo_link">
    <inertial>
      <origin
        xyz="-0.0239032469871357 4.14030477700056E-05 0.0069522010024724"
        rpy="0 0 0" />
      <mass
        value="0.0116329343814783" />
      <inertia
        ixx="2.04910461922326E-06"
        ixy="9.79840941033059E-11"
        ixz="-1.98663153836453E-08"
        iyy="1.75975521005813E-06"
        iyz="2.48825289975981E-13"
        izz="5.57276416756103E-07" />
    </inertial>
    <visual>
      <origin
        xyz="0 0 0"
        rpy="0 0 0" />
      <geometry>
        <mesh
          filename="package://jetauto_description/meshes/arm/servo_link.stl" />
      </geometry>
      <material name="black"/>
    </visual>
    <collision>
      <origin
        xyz="0 0 0"
        rpy="0 0 0" />
      <geometry>
        <mesh
          filename="package://jetauto_description/meshes/arm/servo_link.stl" />
      </geometry>
    </collision>
  </link>
  <joint
    name="servo_joint"
    type="fixed">
    <origin
      xyz="0 0 0"
      rpy="0 0 0" />
    <parent
      link="link1" />
    <child
      link="servo_link" />
    <axis
      xyz="0 0 0" />
  </joint>
  <link
    name="link2">
    <inertial>
      <origin
        xyz="-0.000379251666598135 -0.000106953148182737 0.0722671401198526"
        rpy="0 0 0" />
      <mass
        value="0.0329250074531705" />
      <inertia
        ixx="3.91620966174037E-05"
        ixy="-5.45461883923424E-11"
        ixz="-1.84994427464167E-07"
        iyy="3.08453562297899E-05"
        iyz="3.5881427402197E-09"
        izz="1.15081900975983E-05" />
    </inertial>
    <visual>
      <origin
        xyz="0 0 0"
        rpy="0 0 0" />
      <geometry>
        <mesh
          filename="package://jetauto_description/meshes/arm/link2.stl" />
      </geometry>
      <material name="green"/>
    </visual>
    <collision>
      <origin
        xyz="0 0 0"
        rpy="0 0 0" />
      <geometry>
        <mesh
          filename="package://jetauto_description/meshes/arm/link2.stl" />
      </geometry>
    </collision>
  </link>
  <joint
    name="joint2"
    type="revolute">
    <origin
      xyz="0 1.11027258797025E-05 0.0339293740283087"
      rpy="0 0 0" />
    <parent
      link="servo_link" />
    <child
      link="link2" />
    <axis
      xyz="-1 0 0" />
    <limit
      lower="-1.8326"
      upper="1.8326"
      effort="1000"
      velocity="10" />
  </joint>
  <link
    name="link3">
    <inertial>
      <origin
        xyz="-0.00070372 -0.00019138 0.072342"
        rpy="0 0 0" />
      <mass
        value="0.0329250074463074" />
      <inertia
        ixx="3.91621699579612E-05"
        ixy="-5.40097530558062E-11"
        ixz="-1.73786652512013E-07"
        iyy="3.08451969920239E-05"
        iyz="3.63874236522223E-09"
        izz="1.15078234912494E-05" />
    </inertial>
    <visual>
      <origin
        xyz="0 0 0"
        rpy="0 0 0" />
      <geometry>
        <mesh
          filename="package://jetauto_description/meshes/arm/link3.stl" />
      </geometry>
      <material name="green"/>
    </visual>
    <collision>
      <origin
        xyz="0 0 0"
        rpy="0 0 0" />
      <geometry>
        <mesh
          filename="package://jetauto_description/meshes/arm/link3.stl" />
      </geometry>
    </collision>
  </link>
  <joint
    name="joint3"
    type="revolute">
    <origin
      xyz="0 6.1876E-05 0.12934"
      rpy="0 0 0" />
    <parent
      link="link2" />
    <child
      link="link3" />
    <axis
      xyz="-1 0 0" />
    <limit
      lower="-2.09"
      upper="2.09"
      effort="1000"
      velocity="10" />
  </joint>
  <link
    name="gripper_servo_link">
    <inertial>
      <origin
        xyz="0.00173398274658465 0.0143803550122597 0.0668818334351561"
        rpy="0 0 0" />
      <mass
        value="0.0174988102544488" />
      <inertia
        ixx="1.57024155329016E-06"
        ixy="2.76817630588513E-08"
        ixz="2.23194266007272E-08"
        iyy="4.12618454370932E-06"
        iyz="3.03828124784084E-10"
        izz="3.2611413740062E-06" />
    </inertial>
    <visual>
      <origin
        xyz="0 0 0"
        rpy="0 0 0" />
      <geometry>
        <mesh
          filename="package://jetauto_description/meshes/arm/gripper_servo_link.stl" />
      </geometry>
      <material name="black"/>
    </visual>
    <collision>
      <origin
        xyz="0 0 0"
        rpy="0 0 0" />
      <geometry>
        <mesh
          filename="package://jetauto_description/meshes/arm/gripper_servo_link.stl" />
      </geometry>
    </collision>
  </link>
  <joint
    name="gripper_servo_joint"
    type="fixed">
    <origin
      xyz="0 0 0"
      rpy="0 0 0" />
    <parent
      link="link4" />
    <child
      link="gripper_servo_link" />
    <axis
      xyz="0 0 0" />
  </joint>
  <link
    name="link4">
    <inertial>
      <origin
        xyz="-0.00163514073939064 -1.93455562591538E-06 0.0167299921199148"
        rpy="0 0 0" />
      <mass
        value="0.00959141779390409" />
      <inertia
        ixx="7.94977139591732E-06"
        ixy="-8.29446018776969E-10"
        ixz="5.6880898756802E-08"
        iyy="4.29063067361656E-06"
        iyz="-1.84622131688891E-10"
        izz="5.33833388813501E-06" />
    </inertial>
    <visual>
      <origin
        xyz="0 0 0"
        rpy="0 0 0" />
      <geometry>
        <mesh
          filename="package://jetauto_description/meshes/arm/link4.stl" />
      </geometry>
      <material name="green"/>
    </visual>
    <collision>
      <origin
        xyz="0 0 0"
        rpy="0 0 0" />
      <geometry>
        <mesh
          filename="package://jetauto_description/meshes/arm/link4.stl" />
      </geometry>
    </collision>
  </link>
  <joint
    name="joint4"
    type="revolute">
    <origin
      xyz="0 1.45460570627753E-05 0.129394452413502"
      rpy="0 0 0" />
    <parent
      link="link3" />
    <child
      link="link4" />
    <axis
      xyz="-1 0 0" />
    <limit
      lower="-2.09"
      upper="2.09"
      effort="1000"
      velocity="10" />
  </joint>

  <!-- end effector link -->
  <link name="end_effector_link" />

  <joint name="end_effector_joint" type="fixed">
    <origin xyz="0 0 0.14" rpy="0 0 0"/>
    <parent link="link4"/>
    <child link="end_effector_link"/>
  </joint>

</robot>
